{
  "comments": [
    {
      "key": {
        "uuid": "3fa7e38b_50ff24ff",
        "filename": "upper-constraints.txt",
        "patchSetId": 4
      },
      "lineNbr": 192,
      "author": {
        "id": 5314
      },
      "writtenOn": "2020-01-24T21:17:58Z",
      "side": 1,
      "message": "This is causing the cinder failure.  Happens in py37 also.",
      "range": {
        "startLine": 192,
        "startChar": 0,
        "endLine": 192,
        "endChar": 19
      },
      "revId": "5b4367195a5dd2cbf6f0ee28ee6e92b597a2961b",
      "serverId": "4a232e18-c5a9-48ee-94c0-e04e7cca6543",
      "unresolved": false
    }
  ]
}